Workbook

Sheet 진단일정
A1: 2025년 법정 연구실 정밀안전진단 일정
A2: 1. 안전진단은 건물단위로 모든 연구실험실에 대해서 점검이 실시됩니다. 2. 진단일정은 점검상황, 수업일정 등에 따라 1~2일 이내로 일부 변경(우선점검, 일정보류)될 수 있습니다. 3. 법정진단임으로, 일정에 차질이 생기지 않도록 다음과 같이 협조바랍니다. - 보조키를 사용하는 연구실은 보조키를 반드시 해제, 출입보안장치(KT텔레캅)사용 - 일정 상, 부재 중인 경우에도 본교 직원 입회 하에 점검진행 예정이오니 협조요망 4. 추후 점검결과 미비점 개선결과에 대하여 불시에 캠퍼스안전팀에서 확인예정
A3: 점검일정 | B3: 점검일수 | C3: 점검건물 | D3: 실험실 수
A4: 9월29일(월)~10월 2일(목) | B4: 4 | C4: 자연과학관 | D4: 109
C5: 미래교육관 | D5: 2
C6: 사범대학별관 | D6: 4
C7: 사범대학본관 | D7: 5
A8: 10월10일(금) | B8: 1 | C8: HIT | D8: 20
C9: 제2공학관 | D9: 12
A10: 10월 13일(월) ~ 10월 15일(수) | B10: 3 | C10: 신소재공학관 | D10: 85
A11: 10월 16일(목) ~ 10월 17일(금) | B11: 2 | C11: 퓨전테크센터 | D11: 66
A12: 10월 20일(월) ~ 10월 22일(수) | B12: 3 | C12: 올림픽체육관 | D12: 9
C13: 정보통신관 | D13: 41
C14: 산학기술관 | D14: 48
A15: 10월 23일(목) ~ 10월 24일 | B15: 2 | C15: 과학기술관 | D15: 46
C16: 미래자동차연구센터 | D16: 15
C17: 건축관 | D17: 9
A18: 10월 27일 (월) ~ 10월 29일(수) | B18: 3 | C18: 공업센터본관 | D18: 51
C19: 공업센터별관 | D19: 31
C20: 공업센터보일러동 | D20: 16
A21: 10월 30일(목) | B21: 1 | C21: 토건관 | D21: 15
C22: 재성토목관 | D22: 18
A23: 10월 31일(금) | B23: 1 | C23: 학생회관 | D23: 9
C24: 대학원건물뒤컨테이너실험실 | D24: 1
C25: 제2공학관뒤차량실험실 | D25: 1
C26: 융합교육관 | D26: 4
C27: 구리병원 및 미점검연구실 | D27: 1
A28: 11월 3일 (월) ~ 11월 4일(화) | B28: 2 | C28: 대학병원 동관 | D28: 1
C29: 대학병원 서관 | D29: 1
C30: 제2의학관 | D30: 3
C31: 의대본관 | D31: 26
C32: 제1의학관 | D32: 32
A33: 11월 5일(수) | B33: 1 | C33: 생활과학관 | D33: 21
C34: 진단 강평 | D34: -
A35: 총 계 | B35: =SUM(B4:B34) -> 23 | D35: =SUM(D4:D34) -> 702

Sheet 실험실 LIST
A1: 2025년 법정 연구실 정밀안전진단 대상리스트
A2: <주의사항 : 2025년 9월 18일(목) 현재기준으로 단과대학/관계부서에서 관재팀에 신고된 연구실명단입니다.> 1. 연구실 안전진단은 법정의무 안전진단입니다. 누락사항 발생 시 법적처벌이 발생되오니 단과대학 및 관계부서에서는 철저한 확인요망 --> 벌칙사항 : 5년이하의 징역 또는 5천만원 이하의 벌금(양벌규정에 의해, 대학총장 및 단과대학, 관계자(안전책임자 등)도 처벌됩니다.) 2. 연구실이 삭제되었거나, 이전, 실명변경, 신규설치된 경우, 반드시 캠퍼스안전팀 02-2220-0168, zppr6824@hanyang.ac.kr로 연락요망
A4: 연구실 번호 | B4: 단과대학 | C4: 학과명 | D4: 건물명 | E4: 호 수 | F4: 연구실명 | G4: 분류 | H4: 과학기술분야/예체능 및 기타분야
A5: 한양-072 | B5: 공과대학 행정팀 | C5: 기계공학부 | D5: HIT | E5: 301 | F5: 브릿지융합연구단 | G5: 건축/환경 | H5: =VLOOKUP(A5,[1]이공계구분!$A$2:$K$746,11,0) -> #N/A
A6: 한양-075 | B6: 사업단/센터(연구지원팀) | C6: 지크립토 블록체인 연구소 | D6: HIT | E6: 312 | F6: 지크립토 블록체인 연구소 | G6: 건축/환경 | H6: =VLOOKUP(A6,[1]이공계구분!$A$2:$K$746,11,0) -> #N/A
A7: 한양-007 | B7: 공과대학 행정팀 | C7: 전기공학전공 | D7: HIT | E7: 402 | F7: SEED LAB(402) | G7: 건축/환경 | H7: =VLOOKUP(A7,[1]이공계구분!$A$2:$K$746,11,0) -> 과학기술분야
A8: 한양-079 | B8: 공과대학 행정팀 | C8: 반도체공학과 | D8: HIT | E8: 407 | F8: 반도체공학과 회로설계실험실 | G8: 건축/환경 | H8: =VLOOKUP(A8,[1]이공계구분!$A$2:$K$746,11,0) -> #N/A
A9: 한양-044 | B9: 공과대학 행정팀 | C9: 전기공학전공 | D9: HIT | E9: 408 | F9: SEED LAB(408) | G9: 건축/환경 | H9: =VLOOKUP(A9,[1]이공계구분!$A$2:$K$746,11,0) -> 과학기술분야
A10: 한양-080 | B10: 공간과 문화 종합연구소 | C10: 공간과 문화 종합연구소 | D10: HIT | E10: 423 | F10: 공간과 문화 종합연구소 | G10: 건축/환경 | H10: =VLOOKUP(A10,[1]이공계구분!$A$2:$K$746,11,0) -> #N/A
A11: 한양-017 | B11: 공과대학 행정팀 | C11: 융합전자공학부 | D11: HIT | E11: 503 | F11: 나노SOI공정연구실 | G11: 건축/환경 | H11: =VLOOKUP(A11,[1]이공계구분!$A$2:$K$746,11,0) -> 과학기술분야
A12: 한양-063 | B12: 사업단/센터(연구지원팀) | C12: AI솔루션센터 | D12: HIT | E12: 521 | F12: AI솔루션센터 | G12: 건축/환경 | H12: =VLOOKUP(A12,[1]이공계구분!$A$2:$K$746,11,0) -> 과학기술분야
A13: 한양-064 | B13: 공과대학 행정팀 | C13: 바이오메디컬공학과 | D13: HIT | E13: 314-4 | F13: 뇌-컴퓨터인터페이스연구실 | G13: 기계/물리 | H13: =VLOOKUP(A13,[1]이공계구분!$A$2:$K$746,11,0) -> 과학기술분야
A14: 한양-078 | B14: 공과대학 행정팀 | C14: 신소재공학부 | D14: HIT | E14: 507-2 | F14: 배터리소재측정실 | G14: 건축/환경 | H14: =VLOOKUP(A14,[1]이공계구분!$A$2:$K$746,11,0) -> #N/A
A15: 한양-068 | B15: 공과대학 행정팀 | C15: 기계공학부 | D15: HIT | E15: 507-5 | F15: ADIP Lab | G15: 건축/환경 | H15: =VLOOKUP(A15,[1]이공계구분!$A$2:$K$746,11,0) -> 과학기술분야
A16: 한양-076 | B16: 공과대학 행정팀 | C16: 기계공학부 | D16: HIT | E16: B107 | F16: 산업과학연구소 교수연구실 | G16: 건축/환경 | H16: =VLOOKUP(A16,[1]이공계구분!$A$2:$K$746,11,0) -> #N/A
A17: 한양-040 | B17: 공과대학 행정팀 | C17: 기계공학부 | D17: HIT | E17: B111 | F17: 음향진동실험실 | G17: 건축/환경 | H17: =VLOOKUP(A17,[1]이공계구분!$A$2:$K$746,11,0) -> 과학기술분야
A18: 한양-026 | B18: 신소재공학부(산업소재기술연구소) | C18: 신소재공학부 | D18: HIT | E18: B117 | F18: 산업소재기술연구소 | G18: 기타(산업공학) | H18: =VLOOKUP(A18,[1]이공계구분!$A$2:$K$746,11,0) -> 과학기술분야
A19: 한양-027 | B19: 공과대학 행정팀 | C19: 건축공학부 | D19: HIT | E19: B118(1) | F19: 건축음향연구실 | G19: 기타(산업공학) | H19: =VLOOKUP(A19,[1]이공계구분!$A$2:$K$746,11,0) -> 과학기술분야
A20: 한양-066 | B20: 공과대학 행정팀 | C20: 건축공학부 | D20: HIT | E20: B118(2) | F20: 전진용교수연구실(B118-2) | G20: 화학/화공 | H20: =VLOOKUP(A20,[1]이공계구분!$A$2:$K$746,11,0) -> 과학기술분야
A21: 한양-045 | B21: 공과대학 행정팀 | C21: 기계공학부 | D21: HIT | E21: B118(3) | F21: 나노에너지시스템연구실(B118) | G21: 건축/환경 | H21: =VLOOKUP(A21,[1]이공계구분!$A$2:$K$746,11,0) -> 과학기술분야
A22: 한양-020 | B22: 공과대학 행정팀 | C22: 전기·생체공학부 | D22: HIT | E22: B120(2) | F22: 산업과학연구소 (정진욱 교수) | G22: 건축/환경 | H22: =VLOOKUP(A22,[1]이공계구분!$A$2:$K$746,11,0) -> 과학기술분야
A23: 한양-059 | B23: 공과대학 행정팀 | C23: 전기공학전공 | D23: HIT | E23: B120-1 | F23: 성태현교수연구실 | G23: 건축/환경 | H23: =VLOOKUP(A23,[1]이공계구분!$A$2:$K$746,11,0) -> 과학기술분야
A24: 한양-071 | B24: 사업단/센터(연구지원팀) | C24: 원전해체연구센터 | D24: HIT | E24: B211 | F24: 원전해체연구센터(B211) | G24: 건축/환경 | H24: =VLOOKUP(A24,[1]이공계구분!$A$2:$K$746,11,0) -> #N/A
... A33: 건축-009 | B33: 공과대학 행정팀 | C33: 건축공학부 | D33: 건축관 | E33: 지하2층 | F33: 건축공학부 실험실(구조공학실험실) | G33: 건축/환경 | H33: =VLOOKUP(A33,[1]이공계구분!$A$2:$K$746,11,0) -> 과학기술분야
A34: 공별-057 | B34: 공과대학 행정팀 | C34: 기계공학부 | D34: 공업센터별관 | E34: 103 | F34: 소프트디바이스연구실 | G34: 건축/환경 | H34: =VLOOKUP(A34,[1]이공계구분!$A$2:$K$746,11,0) -> #N/A
A35: 공별-023 | B35: 공과대학 행정팀 | C35: 기계공학부 | D35: 공업센터별관 | E35: 107 | F35: 동력계실(107) | G35: 건축/환경 | H35: =VLOOKUP(A35,[1]이공계구분!$A$2:$K$746,11,0) -> 과학기술분야
A36: 공별-022 | B36: 공과대학 행정팀 | C36: 기계공학부 | D36: 공업센터별관 | E36: 108 | F36: 열공학실험실(108) | G36: 건축/환경 | H36: =VLOOKUP(A36,[1]이공계구분!$A$2:$K$746,11,0) -> 과학기술분야
A37: 공별-060 | B37: 공과대학 행정팀 | C37: 기계공학부 | D37: 공업센터별관 | E37: 110 | F37: (구)메카트로닉스실험실 | G37: 건축/환경 | H37: =VLOOKUP(A37,[1]이공계구분!$A$2:$K$746,11,0) -> #N/A
A38: 공별-017 | B38: 공과대학 행정팀 | C38: 기계공학부 | D38: 공업센터별관 | E38: 207 | F38: 제어계측실험실 | G38: 건축/환경 | H38: =VLOOKUP(A38,[1]이공계구분!$A$2:$K$746,11,0) -> 과학기술분야
A39: 공별-016 | B39: 공과대학 행정팀 | C39: 기계공학부 | D39: 공업센터별관 | E39: 209 | F39: 응용역학실험준비실/공동실험실 | G39: 건축/환경 | H39: =VLOOKUP(A39,[1]이공계구분!$A$2:$K$746,11,0) -> 과학기술분야
A40: 공별-015 | B40: 공과대학 행정팀 | C40: 기계공학부 | D40: 공업센터별관 | E40: 210 | F40: 응용역학실험실/공동실험실 | G40: 건축/환경 | H40: =VLOOKUP(A40,[1]이공계구분!$A$2:$K$746,11,0) -> 과학기술분야
A41: 공별-061 | B41: 공과대학 행정팀 | C41: 전기·생체공학부 | D41: 공업센터별관 | E41: 307 | F41: 차세대 광전자 및 반도체 소자 연구실 | G41: 기계/물리 | H41: =VLOOKUP(A41,[1]이공계구분!$A$2:$K$746,11,0) -> #N/A
A42: 공별-010 | B42: 공과대학 행정팀 | C42: 전기공학전공 | D42: 공업센터별관 | E42: 308 | F42: 플라즈마전자공학연구실 | G42: 기계/물리 | H42: =VLOOKUP(A42,[1]이공계구분!$A$2:$K$746,11,0) -> 과학기술분야
A43: 공별-048 | B43: 공과대학 행정팀 | C43: 기계공학부 | D43: 공업센터별관 | E43: 309 | F43: 학생연구실 | G43: 건축/환경 | H43: =VLOOKUP(A43,[1]이공계구분!$A$2:$K$746,11,0) -> 과학기술분야
A44: 공별-033 | B44: 공과대학 행정팀 | C44: 기계공학부 | D44: 공업센터별관 | E44: 310 | F44: 바이오의료초음파연구실 | G44: 건축/환경 | H44: =VLOOKUP(A44,[1]이공계구분!$A$2:$K$746,11,0) -> 과학기술분야
A45: 공별-005 | B45: 공과대학 행정팀 | C45: 융합전자공학부 | D45: 공업센터별관 | E45: 610 | F45: 광자응용실험실 | G45: 기계/물리 | H45: =VLOOKUP(A45,[1]이공계구분!$A$2:$K$746,11,0) -> 과학기술분야
A46: 공별-025 | B46: 공과대학 행정팀 | C46: 기계공학부 | D46: 공업센터별관 | E46: 105-2 | F46: 분무실험실 | G46: 의학/생물 | H46: =VLOOKUP(A46,[1]이공계구분!$A$2:$K$746,11,0) -> 과학기술분야
A47: 공별-024 | B47: 공과대학 행정팀 | C47: 기계공학부 | D47: 공업센터별관 | E47: 106-2 | F47: 열공학실험준비실 | G47: 에너지/자원 | H47: =VLOOKUP(A47,[1]이공계구분!$A$2:$K$746,11,0) -> 과학기술분야
A48: 공별-021 | B48: 공과대학 행정팀 | C48: 기계공학부 | D48: 공업센터별관 | E48: 109-2 | F48: 제어계측실험준비실 | G48: 에너지/자원 | H48: =VLOOKUP(A48,[1]이공계구분!$A$2:$K$746,11,0) -> 과학기술분야
A49: 공별-009 | B49: 공과대학 행정팀 | C49: 전기공학전공 | D49: 공업센터별관 | E49: 407~408 | F49: 전력전자연구실 | G49: 건축/환경 | H49: =VLOOKUP(A49,[1]이공계구분!$A$2:$K$746,11,0) -> 과학기술분야
...
